## Глава 19. Исключения

### 19.1. Введение

Исключение (exception) — это событие, которое возникает во время выполнения программы и прерывает нормальный поток выполнения инструкций. Когда возникает какая-нибудь ошибка внутри метода, он создает специальный объект, называемый объектом-исключением или, просто, исключением (exception object), который передается системе выполнения. Этот объект содержит информацию об ошибке, включая тип ошибки и состояние программы, в которой произошла ошибка. Создание объекта-исключения и передача его системе выполнения называется броском исключения (throwing an exception).

После броска исключения система пытается найти его обработчик. Система выполнения проходит по стеку вызовов от текущего метода вверх, ища подходящий обработчик исключений. Выбранный обработчик ловит это исключение. Если системе не удается найти подходящий обработчик исключения, то программа завершает свое выполнение.

В Java все классы-исключения являются наследниками от класса `java.lang.Throwable`, который, в свою очередь, имеет подклассы `java.lang.Error` и `java.lang.Exception`. Класс `java.lang.Exception` имеет дочерний класс `java.lang.RuntimeException` (рис. 19.1).

Иерархия основных исключений Java

*Рис. 19.1. Иерархия основных исключений Java*

По соглашению все бросаемые исключения являются наследниками трех классов: `java.lang.Error`, `java.lang.Exception` или `java.lang.RuntimeException`. Технически можно бросить исключение, которое не является наследником этих трех классов, но является наследником `java.lang.Throwable`, но так делать не принято.

Из описанных выше трех классов выходит три вида исключений в Java:

*   **Наследники `java.lang.Error`.** Эти исключения возникают при серьезных ошибках, после которых невозможно нормальное продолжение выполнения программы. Это могут быть различные сбои аппаратуры и т. д. В обычных ситуациях ваш код не должен перехватывать и обрабатывать этот вид исключений.

*   **Наследники `java.lang.RuntimeException`.** Это непроверяемый тип исключений вроде выхода за границу массива или строки, попытка обращения к методу на переменной, которая содержит null, неправильное использование API и т. д. В большинстве своем программа не может ожидать подобных ошибок и восстановиться после них. Подобные исключения возникают из-за ошибок программиста. Приложение может их перехватывать, но в большинстве случаев имеет гораздо больше смысла исправить ошибку, приводящую к подобным исключениям.

*   **Наследники `java.lang.Exception`, которые НЕ являются наследниками `java.lang.RuntimeException`.** Подобный тип исключений называется проверяемыми исключениями (checked exceptions). Это такой тип исключений, который может ожидать хорошо написанная программа и из которых она может восстановить свой обычный ход выполнения. Это может быть попытка открыть файл, к которому нет доступа или которого не существует; проблемы с доступом по сети и т. д. Все исключения являются проверяемыми, кроме наследников `java.lang.Error` и `java.lang.RuntimeException`. Любой метод, который может бросить проверяемое исключение, должен указать это исключение в клаузе `throws`. Для любого кода, который может бросить проверяемое исключение, это исключение должно быть указано в `throws` метода либо должно быть перехвачено с помощью инструкции `try-catch`.

### 19.2. Перехватывание и обработка исключений

Рассмотрите следующий код:

```java
import java.io.*;

class Main {
    public static void main(String[] args) {
        byte[] bytesToWrite = new byte[100];
        OutputStream os = new FileOutputStream("output.file");
        os.write(bytesToWrite);
        os.close();
    }
}
```

На текущий момент этот код не будет компилироваться, т. к. конструктор `FileOutputStream(String name)` может бросать проверяемое исключение `FileNotFoundException`, вызов метода `os.write(byte[] b)` — проверяемое исключение `IOException`, и вызов метода `os.close()` тоже может бросать проверяемое исключение.

Проверяемые исключения, которые может бросать метод или конструктор, указываются с помощью `throws`:

```java
public FileOutputStream(String name) throws FileNotFoundException
public void write(byte[] b) throws IOException
public void close() throws IOException
```

Все проверяемые исключения, которые может бросать код, должны быть указаны в `throws` этого метода, либо должны быть перехвачены и обработаны с помощью `try-catch-finally`.

Чтобы пример выше компилировался, нужно поместить в блок `try` весь код, который может бросить исключения:

```java
// BlockTry.java
package ru.urvanov.javaindynamics2022.exception;

import java.io.*;

class BlockTry {
    public static void main(String[] args) {
        byte[] bytesToWrite = new byte[100];
        try {
            OutputStream os = new FileOutputStream("output.file");
            os.write(bytesToWrite);
            os.close();
        } catch (FileNotFoundException fnfe) {
            System.out.println("Cannot find the file.");
        } catch (IOException ioex) {
            System.out.println("Error writing file: " + ioex.getMessage());
        }
    }
}
```

Теперь в случае возникновения исключения `FileNotFoundException` управление будет передаваться на блок:

```java
catch (FileNotFoundException fnfe) {
    System.out.println("Cannot find the file.");
}
```

Этот блок выведет в консоль строку "Cannot find the file", после чего управление передастся на следующую инструкцию за блоком `try-catch`.

Если же возникнет исключение `IOException` либо один из его потомков (`FileNotFoundException` тоже является потомком `IOException`, но поскольку мы указали его блок первым, то в случае `FileNotFoundException` будет выполняться его специфичный блок), то будет выполняться блок, который выведет в консоль строку "Error writing file: ...", после чего управление передастся на следующую инструкцию за блоком `try-catch`.

Мы также могли сделать свой, отдельный блок `try-catch` для каждой инструкции, которая может бросить исключение.

При возникновении исключения смотрятся блоки `catch` ближайшего блока `try` в том порядке, в котором они объявлены. Среда исполнения пытается сопоставить тип объекта-исключения с типом объекта-исключения, указанного в каждом из блоков `catch`, и выполняется первый блок `catch`, тип обрабатываемого исключения которого совпадает с типом брошенного исключения. Если подходящего блока `catch` не нашлось, то смотрится вышестоящий блок `try` и т. д.

Как уже было показано выше, обработчик исключения может обращаться к методам объекта исключения, который передается ему в качестве параметра.

Начиная с Java 7, можно в одном блоке `catch` перехватывать несколько различных типов исключений, что позволяет уменьшить количество кода:

```java
catch (IOException|SQLException ex) {
    logger.log(ex);
    // ... other code
}
```

Если блок `catch` перехватывает несколько типов исключений, то тогда его параметр неявно `final`, т. е. в примере выше вы не можете присвоить параметру `ex` что-либо в блоке `catch`.

Посмотрим еще раз на фрагмент кода из примера:

```java
OutputStream os = new FileOutputStream("output.file");
os.write(bytesToWrite);
os.close();
```

Последняя строка `os.close()` закрывает файл и освобождает ресурсы системы. Но она сработает только при нормальном ходе выполнения программы. Если какое-нибудь исключение возникнет в конструкторе или в методе `write()`, то метод закрытия потока не выполнится, а значит, будет утечка ресурсов.

Чтобы избежать подобных проблем, освобождение ресурсов нужно осуществлять в блоке `finally`. Код в блоке `finally` выполняется ВСЕГДА после завершения блока `try`, даже в случае возникновения исключения.

Исправленный код:

```java
// BlockFinally.java
package ru.urvanov.javaindynamics2022.exception;

import java.io.*;

class BlockFinally {
    public static void main(String[] args) {
        byte[] bytesToWrite = new byte[100];
        OutputStream os = null;
        try {
            os = new FileOutputStream("output.file");
            os.write(bytesToWrite);
            System.out.println("end try");
        } catch (FileNotFoundException fnfe) {
            System.out.println("Cannot find the file.");
        } catch (IOException ioex) {
            System.out.println("Error writing file: " + ioex.getMessage());
        } finally {
            System.out.println("finally.");
            if (os != null) {
                // Метод close тоже может бросить исключение.
                try {
                    os.close();
                } catch (IOException closeException) {
                    System.out.println("closeException: " + closeException.getMessage());
                }
            }
        }
        System.out.println("End of program.");
    }
}
```

При обычном ходе выполнения этот код выведет в консоль следующее:

```
end try
finally.
End of program.
```

Если же во время открытия файла на запись произойдет ошибка, то вывод может стать таким:

```
Cannot find the file.
finally.
End of program.
```

Как видите, блок `finally` отработал после блока обработки исключений.

Если виртуальная машина Java завершит свое выполнение во время выполнения кода `try` или `catch`, то блок `finally` может НЕ выполниться. Также, если поток будет прерван внутри кода `try` или `catch`, блок `finally` может НЕ выполниться, хотя программа продолжит свое выполнение.

Приведенный выше код можно сделать более понятным, если использовать оператор `try-with-resources`. Любой объект, реализующий интерфейс `java.lang.AutoCloseable`, который включает все объекты, реализующие `java.io.Closeable` (`Closeable` расширяет `AutoCloseable`), например `FileOutputStream`, можно использовать в `try-with-resources`:

```java
// TryWithResources.java
package ru.urvanov.javaindynamics2022.exception;

import java.io.*;

class TryWithResources {
    public static void main(String[] args) {
        byte[] bytesToWrite = new byte[100];
        try (OutputStream os = new FileOutputStream("output.file")) {
            os.write(bytesToWrite);
            System.out.println("end try");
        } catch (FileNotFoundException fnfe) {
            System.out.println("Cannot find the file.");
        } catch (IOException ioex) {
            System.out.println("Error writing file: " + ioex.getMessage());
        }
        // Блок finally уже не нужен, но можно
        // использовать, если хочется.
        System.out.println("End of program.");
    }
}
```

В этом примере `try-with-resources` автоматически вызовет метод `close()`, что освободит ресурсы.

В блоке `try-with-resources` можно указывать несколько ресурсов, тогда они будут открываться слева направо, как указано в блоке, а закрываться справа налево (т. е. в обратном порядке):

```java
try (OutputStream os = new FileOutputStream("output.file");
     FileReader fr = new FileReader("input.txt")) {
    // ...
}
```

Блок `try-with-resources` может не иметь ни секции `catch`, ни `finally`, но обычный блок `try` должен обязательно иметь либо секцию `catch`, либо секцию `finally`, либо обе секции.

Ресурсы блока `try-with-resources` закрываются перед выполнением блоков `catch` и `finally`.

Рассмотрите следующий код:

```java
TryWithResources.java
static String readFirstLineFromFileWithFinallyBlock(String path) throws IOException {
    BufferedReader br = new BufferedReader(new FileReader(path));
    try {
        return br.readLine();
    } finally {
        if (br != null) br.close();
    }
}
```

Если метод `readLine()` бросит исключение, а затем метод `close()` тоже бросит исключение, то метод `readFirstLineFromFileWithFinallyBlock()` бросит исключение из блока `finally`, а исключение из блока `try` будет подавлено.

Если же исключение возникнет в блоке `try` и в блоке, освобождающем ресурсы для `try-with-resources`, то конечное исключение, бросаемое методом, — исключение из блока `try`, т. е. исходное. Это еще одно преимущество использования `try-with-resources`. Исключения, которые были подавлены в блоке `try-with-resources`, можно получить с помощью метода `public final Throwable[] getSuppressed()`.

Метод `close()` в интерфейсе `java.lang.AutoCloseable` объявляет в клаузе `throws` исключение `Exception`, а метод `close()` в `java.io.Closeable` объявляет `IOException`, что позволяет наследникам `AutoCloseable` определять свои, специфичные для своей области, исключения.

### 19.3. Указание типов исключений, бросаемых методом

Если какой-нибудь код внутри метода может бросать проверяемые исключения, то либо эти исключения должны перехватываться и обрабатываться внутри метода, либо метод должен указывать, что он может бросить исключение подобного вида с помощью ключевого слова `throws`:

```java
WildWorld.java
class WildWorld {
    public void someCalculation(int arg1, double arg2)
            throws java.io.IOException, java.sql.SQLException,
            java.lang.IndexOutOfBoundsException {
    }
}
```

Исключение `IndexOutOfBoundsException` является наследником `RuntimeException`, поэтому указывать его необязательно и даже не нужно:

```java
WildWorld.java
class WildWorld {
    public void someCalculation(int arg1, double arg2)
            throws java.io.IOException, java.sql.SQLException {
    }
}
```

### 19.4. Как бросить исключение

Перед тем как вы сможете перехватить исключение, какой-нибудь код должен его бросить/сгенерировать. Любой код может бросить исключение: ваш код, код из пакета, написанного кем-то другим, сама среда Java. Исключение всегда бросается с помощью инструкции `throw`, независимо от того, кто его бросает:

```java
throw objThrowable;
```

Пример:

```java
if (x == null)
    throw new IllegalStateException("Что-то пошло не так");
```

### 19.5. Цепочки исключений

Приложения часто отвечают на исключение бросанием другого исключения. Цепочки исключений позволяют узнать, какое исключение привело к появлению другого.

Следующие методы и конструкторы класса `java.lang.Throwable` помогают работать с цепочками исключений:

*   `Throwable getCause()`
*   `Throwable initCause(Throwable)`
*   `Throwable(String, Throwable)`
*   `Throwable(Throwable)`

Аргумент `Throwable` метода `initCause` и `Throwable` в конструкторах — это исключения, которые привели к текущему исключению. Метод `getCause()` возвращает исключение, которое стало причиной текущего исключения, а метод `initCause` устанавливает причину текущего исключения:

Пример использования цепочки исключений:

```java
try {
} catch (IOException e) {
    throw new SampleException("Другое IOException", e);
}
```

В этом примере при обработке `IOException` создается новое исключение `SampleException`, причина этого присоединяется к цепочке исключений, и цепочка бросается в следующий уровень обработчиков исключений.

Если какой-нибудь код с верхнего уровня обработчиков исключений захочет вывести стек вызовов, то ему нужно будет использовать метод `getStackTrace()`:

```java
catch (Exception cause) {
    StackTraceElement elements[] = cause.getStackTrace();
    for (int n = 0; n < elements.length; n++) {
        System.err.println(elements[n].getFileName()
                + ":" + elements[n].getLineNumber()
                + "-> "
                + elements[n].getMethodName() + "()");
    }
}
```

### 19.6. Создание своих объектов-исключений

Когда вы выбираете исключение, которое будет бросать ваш код в какой-либо ситуации, вы можете выбрать создание своего нового класса исключения.

Свои исключения обычно создаются в том случае, если стандартные исключения Java не подходят для вашей ситуации либо если вам нужно создать свою иерархию исключений для вашей библиотеки или приложения.

Предположим, что если вы описываете игровую логику, то вам, возможно, потребуется различать следующие виды исключений (рис. 19.2).

Возможная иерархия исключений видеоигры

*Рис. 19.2. Возможная иерархия исключений видеоигры*

В качестве родительского класса для своего исключения `GameLogicException` логичнее всего выбрать класс `Exception`, т. к. в нашем случае нужны именно проверяемые исключения.

По соглашению о кодировании в Java имена исключений должны заканчиваться на `Exception`.

Пример возможного кода для исключения `GameLogicException`:

```java
// GameLogicException.java
public class GameLogicException extends Exception {

    // Конструкторы, вызывающие конструкторы базового класса.

    public GameLogicException() {
        super();
    }

    public GameLogicException(String message) {
        super(message);
    }

    public GameLogicException(String message, Throwable cause) {
        super(message, cause);
    }

    public GameLogicException(Throwable cause) {
        super(cause);
    }

    // остальные методы.
}
```

### 19.7. Преимущества исключений

*   Разделение кода обработки ошибок от обычного кода.
*   Распространение информации о произошедшей ошибке вверх по стеку вызовов.
*   Группировка и разделение различных типов ошибок.

